ERROR 2025-01-08 11:32:04,804 log Internal Server Error: /
Traceback (most recent call last):
  File "C:\Users\USER\Desktop\video_editor\venv\Lib\site-packages\django\core\handlers\exception.py", line 55, in inner
    response = get_response(request)
               ^^^^^^^^^^^^^^^^^^^^^
  File "C:\Users\USER\Desktop\video_editor\venv\Lib\site-packages\django\core\handlers\base.py", line 220, in _get_response
    response = response.render()
               ^^^^^^^^^^^^^^^^^
  File "C:\Users\USER\Desktop\video_editor\venv\Lib\site-packages\django\template\response.py", line 114, in render
    self.content = self.rendered_content
                   ^^^^^^^^^^^^^^^^^^^^^
  File "C:\Users\USER\Desktop\video_editor\venv\Lib\site-packages\django\template\response.py", line 90, in rendered_content
    template = self.resolve_template(self.template_name)
               ^^^^^^^^^^^^^^^^^^^^^^^^^^^^^^^^^^^^^^^^^
  File "C:\Users\USER\Desktop\video_editor\venv\Lib\site-packages\django\template\response.py", line 72, in resolve_template
    return select_template(template, using=self.using)
           ^^^^^^^^^^^^^^^^^^^^^^^^^^^^^^^^^^^^^^^^^^^
  File "C:\Users\USER\Desktop\video_editor\venv\Lib\site-packages\django\template\loader.py", line 47, in select_template
    raise TemplateDoesNotExist(", ".join(template_name_list), chain=chain)
django.template.exceptions.TemplateDoesNotExist: index.html
ERROR 2025-01-08 11:32:04,808 basehttp "GET / HTTP/1.1" 500 83499
ERROR 2025-01-08 11:33:14,129 log Internal Server Error: /
Traceback (most recent call last):
  File "C:\Users\USER\Desktop\video_editor\venv\Lib\site-packages\django\core\handlers\exception.py", line 55, in inner
    response = get_response(request)
               ^^^^^^^^^^^^^^^^^^^^^
  File "C:\Users\USER\Desktop\video_editor\venv\Lib\site-packages\django\core\handlers\base.py", line 220, in _get_response
    response = response.render()
               ^^^^^^^^^^^^^^^^^
  File "C:\Users\USER\Desktop\video_editor\venv\Lib\site-packages\django\template\response.py", line 114, in render
    self.content = self.rendered_content
                   ^^^^^^^^^^^^^^^^^^^^^
  File "C:\Users\USER\Desktop\video_editor\venv\Lib\site-packages\django\template\response.py", line 90, in rendered_content
    template = self.resolve_template(self.template_name)
               ^^^^^^^^^^^^^^^^^^^^^^^^^^^^^^^^^^^^^^^^^
  File "C:\Users\USER\Desktop\video_editor\venv\Lib\site-packages\django\template\response.py", line 72, in resolve_template
    return select_template(template, using=self.using)
           ^^^^^^^^^^^^^^^^^^^^^^^^^^^^^^^^^^^^^^^^^^^
  File "C:\Users\USER\Desktop\video_editor\venv\Lib\site-packages\django\template\loader.py", line 47, in select_template
    raise TemplateDoesNotExist(", ".join(template_name_list), chain=chain)
django.template.exceptions.TemplateDoesNotExist: index.html
ERROR 2025-01-08 11:33:14,137 basehttp "GET / HTTP/1.1" 500 83499
ERROR 2025-01-08 11:33:38,582 log Internal Server Error: /
Traceback (most recent call last):
  File "C:\Users\USER\Desktop\video_editor\venv\Lib\site-packages\django\core\handlers\exception.py", line 55, in inner
    response = get_response(request)
               ^^^^^^^^^^^^^^^^^^^^^
  File "C:\Users\USER\Desktop\video_editor\venv\Lib\site-packages\django\core\handlers\base.py", line 220, in _get_response
    response = response.render()
               ^^^^^^^^^^^^^^^^^
  File "C:\Users\USER\Desktop\video_editor\venv\Lib\site-packages\django\template\response.py", line 114, in render
    self.content = self.rendered_content
                   ^^^^^^^^^^^^^^^^^^^^^
  File "C:\Users\USER\Desktop\video_editor\venv\Lib\site-packages\django\template\response.py", line 90, in rendered_content
    template = self.resolve_template(self.template_name)
               ^^^^^^^^^^^^^^^^^^^^^^^^^^^^^^^^^^^^^^^^^
  File "C:\Users\USER\Desktop\video_editor\venv\Lib\site-packages\django\template\response.py", line 72, in resolve_template
    return select_template(template, using=self.using)
           ^^^^^^^^^^^^^^^^^^^^^^^^^^^^^^^^^^^^^^^^^^^
  File "C:\Users\USER\Desktop\video_editor\venv\Lib\site-packages\django\template\loader.py", line 47, in select_template
    raise TemplateDoesNotExist(", ".join(template_name_list), chain=chain)
django.template.exceptions.TemplateDoesNotExist: index.html
ERROR 2025-01-08 11:33:38,590 basehttp "GET / HTTP/1.1" 500 83499
ERROR 2025-01-08 11:57:30,640 log Internal Server Error: /api/videos/upload/
ERROR 2025-01-08 11:58:54,924 log Internal Server Error: /api/videos/upload/
ERROR 2025-01-08 11:58:54,926 basehttp "POST /api/videos/upload/ HTTP/1.1" 500 2938
ERROR 2025-01-08 12:02:30,436 log Internal Server Error: /api/videos/upload/
ERROR 2025-01-08 12:02:30,437 basehttp "POST /api/videos/upload/ HTTP/1.1" 500 2984
ERROR 2025-01-08 13:20:56,201 log Internal Server Error: /api/videos/status/16/
Traceback (most recent call last):
  File "C:\Users\USER\Desktop\video_editor\venv\Lib\site-packages\django\core\handlers\exception.py", line 55, in inner
    response = get_response(request)
               ^^^^^^^^^^^^^^^^^^^^^
  File "C:\Users\USER\Desktop\video_editor\venv\Lib\site-packages\django\core\handlers\base.py", line 197, in _get_response
    response = wrapped_callback(request, *callback_args, **callback_kwargs)
               ^^^^^^^^^^^^^^^^^^^^^^^^^^^^^^^^^^^^^^^^^^^^^^^^^^^^^^^^^^^^
  File "C:\Users\USER\Desktop\video_editor\video_processing\views.py", line 66, in video_status
    'status': video.processing_status,  # e.g., "in_progress", "completed"
              ^^^^^^^^^^^^^^^^^^^^^^^
AttributeError: 'UploadedVideo' object has no attribute 'processing_status'
ERROR 2025-01-08 13:20:56,216 basehttp "GET /api/videos/status/16/ HTTP/1.1" 500 69388
ERROR 2025-01-08 13:23:02,407 log Internal Server Error: /api/videos/status/17/
Traceback (most recent call last):
  File "C:\Users\USER\Desktop\video_editor\venv\Lib\site-packages\django\core\handlers\exception.py", line 55, in inner
    response = get_response(request)
               ^^^^^^^^^^^^^^^^^^^^^
  File "C:\Users\USER\Desktop\video_editor\venv\Lib\site-packages\django\core\handlers\base.py", line 197, in _get_response
    response = wrapped_callback(request, *callback_args, **callback_kwargs)
               ^^^^^^^^^^^^^^^^^^^^^^^^^^^^^^^^^^^^^^^^^^^^^^^^^^^^^^^^^^^^
  File "C:\Users\USER\Desktop\video_editor\video_processing\views.py", line 66, in video_status
    'status': video.processing_status,  # e.g., "in_progress", "completed"
              ^^^^^^^^^^^^^^^^^^^^^^^
AttributeError: 'UploadedVideo' object has no attribute 'processing_status'
ERROR 2025-01-08 13:23:02,422 basehttp "GET /api/videos/status/17/ HTTP/1.1" 500 69388
ERROR 2025-01-09 18:30:08,354 log Internal Server Error: /api/videos/upload/
Traceback (most recent call last):
  File "C:\Users\USER\Desktop\video_editor\venv\Lib\site-packages\django\core\handlers\exception.py", line 55, in inner
    response = get_response(request)
               ^^^^^^^^^^^^^^^^^^^^^
  File "C:\Users\USER\Desktop\video_editor\venv\Lib\site-packages\django\core\handlers\base.py", line 197, in _get_response
    response = wrapped_callback(request, *callback_args, **callback_kwargs)
               ^^^^^^^^^^^^^^^^^^^^^^^^^^^^^^^^^^^^^^^^^^^^^^^^^^^^^^^^^^^^
  File "C:\Users\USER\Desktop\video_editor\venv\Lib\site-packages\django\views\decorators\csrf.py", line 65, in _view_wrapper
    return view_func(request, *args, **kwargs)
           ^^^^^^^^^^^^^^^^^^^^^^^^^^^^^^^^^^^
  File "C:\Users\USER\Desktop\video_editor\venv\Lib\site-packages\django\views\generic\base.py", line 104, in view
    return self.dispatch(request, *args, **kwargs)
           ^^^^^^^^^^^^^^^^^^^^^^^^^^^^^^^^^^^^^^^
  File "C:\Users\USER\Desktop\video_editor\venv\Lib\site-packages\rest_framework\views.py", line 509, in dispatch
    response = self.handle_exception(exc)
               ^^^^^^^^^^^^^^^^^^^^^^^^^^
  File "C:\Users\USER\Desktop\video_editor\venv\Lib\site-packages\rest_framework\views.py", line 469, in handle_exception
    self.raise_uncaught_exception(exc)
  File "C:\Users\USER\Desktop\video_editor\venv\Lib\site-packages\rest_framework\views.py", line 480, in raise_uncaught_exception
    raise exc
  File "C:\Users\USER\Desktop\video_editor\venv\Lib\site-packages\rest_framework\views.py", line 506, in dispatch
    response = handler(request, *args, **kwargs)
               ^^^^^^^^^^^^^^^^^^^^^^^^^^^^^^^^^
  File "C:\Users\USER\Desktop\video_editor\video_processing\views.py", line 120, in post
    if serializer.is_valid():
       ^^^^^^^^^^^^^^^^^^^^^
  File "C:\Users\USER\Desktop\video_editor\venv\Lib\site-packages\rest_framework\serializers.py", line 223, in is_valid
    self._validated_data = self.run_validation(self.initial_data)
                           ^^^^^^^^^^^^^^^^^^^^^^^^^^^^^^^^^^^^^^
  File "C:\Users\USER\Desktop\video_editor\venv\Lib\site-packages\rest_framework\serializers.py", line 442, in run_validation
    value = self.to_internal_value(data)
            ^^^^^^^^^^^^^^^^^^^^^^^^^^^^
  File "C:\Users\USER\Desktop\video_editor\venv\Lib\site-packages\rest_framework\serializers.py", line 495, in to_internal_value
    for field in fields:
                 ^^^^^^
  File "C:\Users\USER\Desktop\video_editor\venv\Lib\site-packages\rest_framework\serializers.py", line 378, in _writable_fields
    for field in self.fields.values():
                 ^^^^^^^^^^^
  File "C:\Users\USER\Desktop\video_editor\venv\Lib\site-packages\django\utils\functional.py", line 47, in __get__
    res = instance.__dict__[self.name] = self.func(instance)
                                         ^^^^^^^^^^^^^^^^^^^
  File "C:\Users\USER\Desktop\video_editor\venv\Lib\site-packages\rest_framework\serializers.py", line 372, in fields
    for key, value in self.get_fields().items():
                      ^^^^^^^^^^^^^^^^^
  File "C:\Users\USER\Desktop\video_editor\venv\Lib\site-packages\rest_framework\serializers.py", line 1103, in get_fields
    field_class, field_kwargs = self.build_field(
                                ^^^^^^^^^^^^^^^^^
  File "C:\Users\USER\Desktop\video_editor\venv\Lib\site-packages\rest_framework\serializers.py", line 1249, in build_field
    return self.build_unknown_field(field_name, model_class)
           ^^^^^^^^^^^^^^^^^^^^^^^^^^^^^^^^^^^^^^^^^^^^^^^^^
  File "C:\Users\USER\Desktop\video_editor\venv\Lib\site-packages\rest_framework\serializers.py", line 1367, in build_unknown_field
    raise ImproperlyConfigured(
django.core.exceptions.ImproperlyConfigured: Field name `uploaded_at` is not valid for model `UploadedVideo` in `video_processing.serializers.UploadedVideoSerializer`.
ERROR 2025-01-09 18:30:08,376 basehttp "POST /api/videos/upload/ HTTP/1.1" 500 140908
ERROR 2025-01-09 18:34:59,064 log Internal Server Error: /api/videos/upload/
Traceback (most recent call last):
  File "C:\Users\USER\Desktop\video_editor\venv\Lib\site-packages\django\core\handlers\exception.py", line 55, in inner
    response = get_response(request)
               ^^^^^^^^^^^^^^^^^^^^^
  File "C:\Users\USER\Desktop\video_editor\venv\Lib\site-packages\django\core\handlers\base.py", line 197, in _get_response
    response = wrapped_callback(request, *callback_args, **callback_kwargs)
               ^^^^^^^^^^^^^^^^^^^^^^^^^^^^^^^^^^^^^^^^^^^^^^^^^^^^^^^^^^^^
  File "C:\Users\USER\Desktop\video_editor\venv\Lib\site-packages\django\views\decorators\csrf.py", line 65, in _view_wrapper
    return view_func(request, *args, **kwargs)
           ^^^^^^^^^^^^^^^^^^^^^^^^^^^^^^^^^^^
  File "C:\Users\USER\Desktop\video_editor\venv\Lib\site-packages\django\views\generic\base.py", line 104, in view
    return self.dispatch(request, *args, **kwargs)
           ^^^^^^^^^^^^^^^^^^^^^^^^^^^^^^^^^^^^^^^
  File "C:\Users\USER\Desktop\video_editor\venv\Lib\site-packages\rest_framework\views.py", line 509, in dispatch
    response = self.handle_exception(exc)
               ^^^^^^^^^^^^^^^^^^^^^^^^^^
  File "C:\Users\USER\Desktop\video_editor\venv\Lib\site-packages\rest_framework\views.py", line 469, in handle_exception
    self.raise_uncaught_exception(exc)
  File "C:\Users\USER\Desktop\video_editor\venv\Lib\site-packages\rest_framework\views.py", line 480, in raise_uncaught_exception
    raise exc
  File "C:\Users\USER\Desktop\video_editor\venv\Lib\site-packages\rest_framework\views.py", line 506, in dispatch
    response = handler(request, *args, **kwargs)
               ^^^^^^^^^^^^^^^^^^^^^^^^^^^^^^^^^
  File "C:\Users\USER\Desktop\video_editor\video_processing\views.py", line 120, in post
    if serializer.is_valid():
       ^^^^^^^^^^^^^^^^^^^^^
  File "C:\Users\USER\Desktop\video_editor\venv\Lib\site-packages\rest_framework\serializers.py", line 223, in is_valid
    self._validated_data = self.run_validation(self.initial_data)
                           ^^^^^^^^^^^^^^^^^^^^^^^^^^^^^^^^^^^^^^
  File "C:\Users\USER\Desktop\video_editor\venv\Lib\site-packages\rest_framework\serializers.py", line 442, in run_validation
    value = self.to_internal_value(data)
            ^^^^^^^^^^^^^^^^^^^^^^^^^^^^
  File "C:\Users\USER\Desktop\video_editor\venv\Lib\site-packages\rest_framework\serializers.py", line 495, in to_internal_value
    for field in fields:
                 ^^^^^^
  File "C:\Users\USER\Desktop\video_editor\venv\Lib\site-packages\rest_framework\serializers.py", line 378, in _writable_fields
    for field in self.fields.values():
                 ^^^^^^^^^^^
  File "C:\Users\USER\Desktop\video_editor\venv\Lib\site-packages\django\utils\functional.py", line 47, in __get__
    res = instance.__dict__[self.name] = self.func(instance)
                                         ^^^^^^^^^^^^^^^^^^^
  File "C:\Users\USER\Desktop\video_editor\venv\Lib\site-packages\rest_framework\serializers.py", line 372, in fields
    for key, value in self.get_fields().items():
                      ^^^^^^^^^^^^^^^^^
  File "C:\Users\USER\Desktop\video_editor\venv\Lib\site-packages\rest_framework\serializers.py", line 1103, in get_fields
    field_class, field_kwargs = self.build_field(
                                ^^^^^^^^^^^^^^^^^
  File "C:\Users\USER\Desktop\video_editor\venv\Lib\site-packages\rest_framework\serializers.py", line 1249, in build_field
    return self.build_unknown_field(field_name, model_class)
           ^^^^^^^^^^^^^^^^^^^^^^^^^^^^^^^^^^^^^^^^^^^^^^^^^
  File "C:\Users\USER\Desktop\video_editor\venv\Lib\site-packages\rest_framework\serializers.py", line 1367, in build_unknown_field
    raise ImproperlyConfigured(
django.core.exceptions.ImproperlyConfigured: Field name `uploaded_at` is not valid for model `UploadedVideo` in `video_processing.serializers.UploadedVideoSerializer`.
ERROR 2025-01-09 18:34:59,080 basehttp "POST /api/videos/upload/ HTTP/1.1" 500 140907
ERROR 2025-01-09 18:38:36,924 log Internal Server Error: /api/videos/status/34/
Traceback (most recent call last):
  File "C:\Users\USER\Desktop\video_editor\venv\Lib\site-packages\django\core\handlers\exception.py", line 55, in inner
    response = get_response(request)
               ^^^^^^^^^^^^^^^^^^^^^
  File "C:\Users\USER\Desktop\video_editor\venv\Lib\site-packages\django\core\handlers\base.py", line 197, in _get_response
    response = wrapped_callback(request, *callback_args, **callback_kwargs)
               ^^^^^^^^^^^^^^^^^^^^^^^^^^^^^^^^^^^^^^^^^^^^^^^^^^^^^^^^^^^^
  File "C:\Users\USER\Desktop\video_editor\video_processing\views.py", line 158, in video_status
    "status": video.processing_status,
              ^^^^^^^^^^^^^^^^^^^^^^^
AttributeError: 'UploadedVideo' object has no attribute 'processing_status'
ERROR 2025-01-09 18:38:36,955 basehttp "GET /api/videos/status/34/ HTTP/1.1" 500 69261
ERROR 2025-01-09 18:53:00,372 log Internal Server Error: /api/videos/status/35/
Traceback (most recent call last):
  File "C:\Users\USER\Desktop\video_editor\venv\Lib\site-packages\django\core\handlers\exception.py", line 55, in inner
    response = get_response(request)
               ^^^^^^^^^^^^^^^^^^^^^
  File "C:\Users\USER\Desktop\video_editor\venv\Lib\site-packages\django\core\handlers\base.py", line 197, in _get_response
    response = wrapped_callback(request, *callback_args, **callback_kwargs)
               ^^^^^^^^^^^^^^^^^^^^^^^^^^^^^^^^^^^^^^^^^^^^^^^^^^^^^^^^^^^^
  File "C:\Users\USER\Desktop\video_editor\video_processing\views.py", line 156, in video_status
    "status": video.processing_status,
              ^^^^^^^^^^^^^^^^^^^^^^^
AttributeError: 'UploadedVideo' object has no attribute 'processing_status'
ERROR 2025-01-09 18:53:00,389 basehttp "GET /api/videos/status/35/ HTTP/1.1" 500 69269
ERROR 2025-01-09 19:07:40,131 log Internal Server Error: /
Traceback (most recent call last):
  File "C:\Users\USER\Desktop\video_editor\venv\Lib\site-packages\django\core\handlers\exception.py", line 55, in inner
    response = get_response(request)
               ^^^^^^^^^^^^^^^^^^^^^
  File "C:\Users\USER\Desktop\video_editor\venv\Lib\site-packages\django\core\handlers\base.py", line 220, in _get_response
    response = response.render()
               ^^^^^^^^^^^^^^^^^
  File "C:\Users\USER\Desktop\video_editor\venv\Lib\site-packages\django\template\response.py", line 114, in render
    self.content = self.rendered_content
                   ^^^^^^^^^^^^^^^^^^^^^
  File "C:\Users\USER\Desktop\video_editor\venv\Lib\site-packages\django\template\response.py", line 90, in rendered_content
    template = self.resolve_template(self.template_name)
               ^^^^^^^^^^^^^^^^^^^^^^^^^^^^^^^^^^^^^^^^^
  File "C:\Users\USER\Desktop\video_editor\venv\Lib\site-packages\django\template\response.py", line 72, in resolve_template
    return select_template(template, using=self.using)
           ^^^^^^^^^^^^^^^^^^^^^^^^^^^^^^^^^^^^^^^^^^^
  File "C:\Users\USER\Desktop\video_editor\venv\Lib\site-packages\django\template\loader.py", line 47, in select_template
    raise TemplateDoesNotExist(", ".join(template_name_list), chain=chain)
django.template.exceptions.TemplateDoesNotExist: index.html
ERROR 2025-01-09 19:07:40,140 basehttp "GET / HTTP/1.1" 500 84261
ERROR 2025-01-09 19:10:24,413 log Internal Server Error: /
Traceback (most recent call last):
  File "C:\Users\USER\Desktop\video_editor\venv\Lib\site-packages\django\core\handlers\exception.py", line 55, in inner
    response = get_response(request)
               ^^^^^^^^^^^^^^^^^^^^^
  File "C:\Users\USER\Desktop\video_editor\venv\Lib\site-packages\django\core\handlers\base.py", line 220, in _get_response
    response = response.render()
               ^^^^^^^^^^^^^^^^^
  File "C:\Users\USER\Desktop\video_editor\venv\Lib\site-packages\django\template\response.py", line 114, in render
    self.content = self.rendered_content
                   ^^^^^^^^^^^^^^^^^^^^^
  File "C:\Users\USER\Desktop\video_editor\venv\Lib\site-packages\django\template\response.py", line 90, in rendered_content
    template = self.resolve_template(self.template_name)
               ^^^^^^^^^^^^^^^^^^^^^^^^^^^^^^^^^^^^^^^^^
  File "C:\Users\USER\Desktop\video_editor\venv\Lib\site-packages\django\template\response.py", line 72, in resolve_template
    return select_template(template, using=self.using)
           ^^^^^^^^^^^^^^^^^^^^^^^^^^^^^^^^^^^^^^^^^^^
  File "C:\Users\USER\Desktop\video_editor\venv\Lib\site-packages\django\template\loader.py", line 47, in select_template
    raise TemplateDoesNotExist(", ".join(template_name_list), chain=chain)
django.template.exceptions.TemplateDoesNotExist: index.html
ERROR 2025-01-09 19:10:24,413 basehttp "GET / HTTP/1.1" 500 84261
ERROR 2025-01-09 20:28:59,995 log Internal Server Error: /api/videos/status/49/
Traceback (most recent call last):
  File "C:\Users\USER\Desktop\video_editor\venv\Lib\site-packages\django\core\handlers\exception.py", line 55, in inner
    response = get_response(request)
               ^^^^^^^^^^^^^^^^^^^^^
  File "C:\Users\USER\Desktop\video_editor\venv\Lib\site-packages\django\core\handlers\base.py", line 197, in _get_response
    response = wrapped_callback(request, *callback_args, **callback_kwargs)
               ^^^^^^^^^^^^^^^^^^^^^^^^^^^^^^^^^^^^^^^^^^^^^^^^^^^^^^^^^^^^
  File "C:\Users\USER\Desktop\video_editor\video_processing\views.py", line 172, in video_status
    video_url = video.processed_file.url
                ^^^^^^^^^^^^^^^^^^^^^^^^
  File "C:\Users\USER\Desktop\video_editor\venv\Lib\site-packages\django\db\models\fields\files.py", line 69, in url
    self._require_file()
  File "C:\Users\USER\Desktop\video_editor\venv\Lib\site-packages\django\db\models\fields\files.py", line 44, in _require_file
    raise ValueError(
ValueError: The 'processed_file' attribute has no file associated with it.
ERROR 2025-01-09 20:29:00,015 basehttp "GET /api/videos/status/49/ HTTP/1.1" 500 75619
ERROR 2025-01-09 20:31:56,737 log Internal Server Error: /api/videos/status/50/
ERROR 2025-01-09 20:31:56,740 basehttp "GET /api/videos/status/50/ HTTP/1.1" 500 63
ERROR 2025-01-09 20:33:00,954 log Internal Server Error: /api/videos/status/51/
Traceback (most recent call last):
  File "C:\Users\USER\Desktop\video_editor\venv\Lib\site-packages\django\core\handlers\exception.py", line 55, in inner
    response = get_response(request)
               ^^^^^^^^^^^^^^^^^^^^^
  File "C:\Users\USER\Desktop\video_editor\venv\Lib\site-packages\django\core\handlers\base.py", line 197, in _get_response
    response = wrapped_callback(request, *callback_args, **callback_kwargs)
               ^^^^^^^^^^^^^^^^^^^^^^^^^^^^^^^^^^^^^^^^^^^^^^^^^^^^^^^^^^^^
  File "C:\Users\USER\Desktop\video_editor\video_processing\views.py", line 173, in video_status
    video_url = video.processed_file.url
                ^^^^^^^^^^^^^^^^^^^^^^^^
  File "C:\Users\USER\Desktop\video_editor\venv\Lib\site-packages\django\db\models\fields\files.py", line 69, in url
    self._require_file()
  File "C:\Users\USER\Desktop\video_editor\venv\Lib\site-packages\django\db\models\fields\files.py", line 44, in _require_file
    raise ValueError(
ValueError: The 'processed_file' attribute has no file associated with it.
ERROR 2025-01-09 20:33:00,967 basehttp "GET /api/videos/status/51/ HTTP/1.1" 500 75665
ERROR 2025-01-11 16:29:38,743 log Internal Server Error: /api/videos/upload/
Traceback (most recent call last):
  File "C:\Users\USER\OneDrive\video_editor\video_processing_app\video_processing\views.py", line 111, in process_video
    video_instance.save()
  File "C:\Users\USER\Desktop\video_editor\venv\Lib\site-packages\django\db\models\base.py", line 892, in save
    self.save_base(
  File "C:\Users\USER\Desktop\video_editor\venv\Lib\site-packages\django\db\models\base.py", line 998, in save_base
    updated = self._save_table(
              ^^^^^^^^^^^^^^^^^
  File "C:\Users\USER\Desktop\video_editor\venv\Lib\site-packages\django\db\models\base.py", line 1130, in _save_table
    updated = self._do_update(
              ^^^^^^^^^^^^^^^^
  File "C:\Users\USER\Desktop\video_editor\venv\Lib\site-packages\django\db\models\base.py", line 1195, in _do_update
    return filtered._update(values) > 0
           ^^^^^^^^^^^^^^^^^^^^^^^^
  File "C:\Users\USER\Desktop\video_editor\venv\Lib\site-packages\django\db\models\query.py", line 1278, in _update
    return query.get_compiler(self.db).execute_sql(CURSOR)
           ^^^^^^^^^^^^^^^^^^^^^^^^^^^^^^^^^^^^^^^^^^^^^^^
  File "C:\Users\USER\Desktop\video_editor\venv\Lib\site-packages\django\db\models\sql\compiler.py", line 2003, in execute_sql
    cursor = super().execute_sql(result_type)
             ^^^^^^^^^^^^^^^^^^^^^^^^^^^^^^^^
  File "C:\Users\USER\Desktop\video_editor\venv\Lib\site-packages\django\db\models\sql\compiler.py", line 1572, in execute_sql
    cursor = self.connection.cursor()
             ^^^^^^^^^^^^^^^^^^^^^^^^
  File "C:\Users\USER\Desktop\video_editor\venv\Lib\site-packages\django\utils\asyncio.py", line 24, in inner
    raise SynchronousOnlyOperation(message)
django.core.exceptions.SynchronousOnlyOperation: You cannot call this from an async context - use a thread or sync_to_async.

During handling of the above exception, another exception occurred:

Traceback (most recent call last):
  File "C:\Users\USER\OneDrive\video_editor\video_processing_app\video_processing\views.py", line 140, in process_video
    video_instance.save()
  File "C:\Users\USER\Desktop\video_editor\venv\Lib\site-packages\django\db\models\base.py", line 892, in save
    self.save_base(
  File "C:\Users\USER\Desktop\video_editor\venv\Lib\site-packages\django\db\models\base.py", line 998, in save_base
    updated = self._save_table(
              ^^^^^^^^^^^^^^^^^
  File "C:\Users\USER\Desktop\video_editor\venv\Lib\site-packages\django\db\models\base.py", line 1130, in _save_table
    updated = self._do_update(
              ^^^^^^^^^^^^^^^^
  File "C:\Users\USER\Desktop\video_editor\venv\Lib\site-packages\django\db\models\base.py", line 1195, in _do_update
    return filtered._update(values) > 0
           ^^^^^^^^^^^^^^^^^^^^^^^^
  File "C:\Users\USER\Desktop\video_editor\venv\Lib\site-packages\django\db\models\query.py", line 1278, in _update
    return query.get_compiler(self.db).execute_sql(CURSOR)
           ^^^^^^^^^^^^^^^^^^^^^^^^^^^^^^^^^^^^^^^^^^^^^^^
  File "C:\Users\USER\Desktop\video_editor\venv\Lib\site-packages\django\db\models\sql\compiler.py", line 2003, in execute_sql
    cursor = super().execute_sql(result_type)
             ^^^^^^^^^^^^^^^^^^^^^^^^^^^^^^^^
  File "C:\Users\USER\Desktop\video_editor\venv\Lib\site-packages\django\db\models\sql\compiler.py", line 1572, in execute_sql
    cursor = self.connection.cursor()
             ^^^^^^^^^^^^^^^^^^^^^^^^
  File "C:\Users\USER\Desktop\video_editor\venv\Lib\site-packages\django\utils\asyncio.py", line 24, in inner
    raise SynchronousOnlyOperation(message)
django.core.exceptions.SynchronousOnlyOperation: You cannot call this from an async context - use a thread or sync_to_async.

During handling of the above exception, another exception occurred:

Traceback (most recent call last):
  File "C:\Users\USER\Desktop\video_editor\venv\Lib\site-packages\django\core\handlers\exception.py", line 55, in inner
    response = get_response(request)
               ^^^^^^^^^^^^^^^^^^^^^
  File "C:\Users\USER\Desktop\video_editor\venv\Lib\site-packages\django\core\handlers\base.py", line 197, in _get_response
    response = wrapped_callback(request, *callback_args, **callback_kwargs)
               ^^^^^^^^^^^^^^^^^^^^^^^^^^^^^^^^^^^^^^^^^^^^^^^^^^^^^^^^^^^^
  File "C:\Users\USER\Desktop\video_editor\venv\Lib\site-packages\django\views\decorators\csrf.py", line 65, in _view_wrapper
    return view_func(request, *args, **kwargs)
           ^^^^^^^^^^^^^^^^^^^^^^^^^^^^^^^^^^^
  File "C:\Users\USER\Desktop\video_editor\venv\Lib\site-packages\django\views\generic\base.py", line 104, in view
    return self.dispatch(request, *args, **kwargs)
           ^^^^^^^^^^^^^^^^^^^^^^^^^^^^^^^^^^^^^^^
  File "C:\Users\USER\Desktop\video_editor\venv\Lib\site-packages\rest_framework\views.py", line 509, in dispatch
    response = self.handle_exception(exc)
               ^^^^^^^^^^^^^^^^^^^^^^^^^^
  File "C:\Users\USER\Desktop\video_editor\venv\Lib\site-packages\rest_framework\views.py", line 469, in handle_exception
    self.raise_uncaught_exception(exc)
  File "C:\Users\USER\Desktop\video_editor\venv\Lib\site-packages\rest_framework\views.py", line 480, in raise_uncaught_exception
    raise exc
  File "C:\Users\USER\Desktop\video_editor\venv\Lib\site-packages\rest_framework\views.py", line 506, in dispatch
    response = handler(request, *args, **kwargs)
               ^^^^^^^^^^^^^^^^^^^^^^^^^^^^^^^^^
  File "C:\Users\USER\OneDrive\video_editor\video_processing_app\video_processing\views.py", line 169, in post
    asyncio.run(process_video(input_path, output_path, video_instance))
  File "C:\Program Files\WindowsApps\PythonSoftwareFoundation.Python.3.12_3.12.2288.0_x64__qbz5n2kfra8p0\Lib\asyncio\runners.py", line 194, in run
    return runner.run(main)
           ^^^^^^^^^^^^^^^^
  File "C:\Program Files\WindowsApps\PythonSoftwareFoundation.Python.3.12_3.12.2288.0_x64__qbz5n2kfra8p0\Lib\asyncio\runners.py", line 118, in run
    return self._loop.run_until_complete(task)
           ^^^^^^^^^^^^^^^^^^^^^^^^^^^^^^^^^^^
  File "C:\Program Files\WindowsApps\PythonSoftwareFoundation.Python.3.12_3.12.2288.0_x64__qbz5n2kfra8p0\Lib\asyncio\base_events.py", line 686, in run_until_complete
    return future.result()
           ^^^^^^^^^^^^^^^
  File "C:\Users\USER\OneDrive\video_editor\video_processing_app\video_processing\views.py", line 145, in process_video
    for segment in os.listdir(temp_segment_dir):
                   ^^^^^^^^^^^^^^^^^^^^^^^^^^^^
FileNotFoundError: [WinError 3] The system cannot find the path specified: 'temp_audio_segments'
ERROR 2025-01-11 16:29:38,838 basehttp "POST /api/videos/upload/ HTTP/1.1" 500 213848
ERROR 2025-01-11 16:33:26,043 log Internal Server Error: /api/videos/upload/
Traceback (most recent call last):
  File "C:\Users\USER\Desktop\video_editor\venv\Lib\site-packages\django\core\handlers\exception.py", line 55, in inner
    response = get_response(request)
               ^^^^^^^^^^^^^^^^^^^^^
  File "C:\Users\USER\Desktop\video_editor\venv\Lib\site-packages\django\core\handlers\base.py", line 197, in _get_response
    response = wrapped_callback(request, *callback_args, **callback_kwargs)
               ^^^^^^^^^^^^^^^^^^^^^^^^^^^^^^^^^^^^^^^^^^^^^^^^^^^^^^^^^^^^
  File "C:\Users\USER\Desktop\video_editor\venv\Lib\site-packages\asgiref\sync.py", line 254, in __call__
    return call_result.result()
           ^^^^^^^^^^^^^^^^^^^^
  File "C:\Program Files\WindowsApps\PythonSoftwareFoundation.Python.3.12_3.12.2288.0_x64__qbz5n2kfra8p0\Lib\concurrent\futures\_base.py", line 449, in result
    return self.__get_result()
           ^^^^^^^^^^^^^^^^^^^
  File "C:\Program Files\WindowsApps\PythonSoftwareFoundation.Python.3.12_3.12.2288.0_x64__qbz5n2kfra8p0\Lib\concurrent\futures\_base.py", line 401, in __get_result
    raise self._exception
  File "C:\Users\USER\Desktop\video_editor\venv\Lib\site-packages\asgiref\sync.py", line 331, in main_wrap
    result = await self.awaitable(*args, **kwargs)
             ^^^^^^^^^^^^^^^^^^^^^^^^^^^^^^^^^^^^^
  File "C:\Users\USER\Desktop\video_editor\venv\Lib\site-packages\django\views\decorators\csrf.py", line 60, in _view_wrapper
    return await view_func(request, *args, **kwargs)
                 ^^^^^^^^^^^^^^^^^^^^^^^^^^^^^^^^^^^
  File "C:\Users\USER\Desktop\video_editor\venv\Lib\site-packages\django\views\generic\base.py", line 104, in view
    return self.dispatch(request, *args, **kwargs)
           ^^^^^^^^^^^^^^^^^^^^^^^^^^^^^^^^^^^^^^^
  File "C:\Users\USER\Desktop\video_editor\venv\Lib\site-packages\rest_framework\views.py", line 511, in dispatch
    self.response = self.finalize_response(request, response, *args, **kwargs)
                    ^^^^^^^^^^^^^^^^^^^^^^^^^^^^^^^^^^^^^^^^^^^^^^^^^^^^^^^^^^
  File "C:\Users\USER\Desktop\video_editor\venv\Lib\site-packages\rest_framework\views.py", line 423, in finalize_response
    assert isinstance(response, HttpResponseBase), (
           ^^^^^^^^^^^^^^^^^^^^^^^^^^^^^^^^^^^^^^
AssertionError: Expected a `Response`, `HttpResponse` or `StreamingHttpResponse` to be returned from the view, but received a `<class 'coroutine'>`
ERROR 2025-01-11 16:33:26,134 basehttp "POST /api/videos/upload/ HTTP/1.1" 500 92309
ERROR 2025-01-11 16:55:33,417 log Internal Server Error: /api/videos/status/109/
Traceback (most recent call last):
  File "C:\Users\USER\Desktop\video_editor\venv\Lib\site-packages\django\core\handlers\exception.py", line 55, in inner
    response = get_response(request)
               ^^^^^^^^^^^^^^^^^^^^^
  File "C:\Users\USER\Desktop\video_editor\venv\Lib\site-packages\django\core\handlers\base.py", line 197, in _get_response
    response = wrapped_callback(request, *callback_args, **callback_kwargs)
               ^^^^^^^^^^^^^^^^^^^^^^^^^^^^^^^^^^^^^^^^^^^^^^^^^^^^^^^^^^^^
  File "C:\Users\USER\OneDrive\video_editor\video_processing_app\video_processing\views.py", line 224, in video_status
    "transcription": video.transcription,
                     ^^^^^^^^^^^^^^^^^^^
AttributeError: 'UploadedVideo' object has no attribute 'transcription'
ERROR 2025-01-11 16:55:33,441 basehttp "GET /api/videos/status/109/ HTTP/1.1" 500 69081
ERROR 2025-01-11 16:56:40,374 log Internal Server Error: /api/videos/status/110/
Traceback (most recent call last):
  File "C:\Users\USER\Desktop\video_editor\venv\Lib\site-packages\django\core\handlers\exception.py", line 55, in inner
    response = get_response(request)
               ^^^^^^^^^^^^^^^^^^^^^
  File "C:\Users\USER\Desktop\video_editor\venv\Lib\site-packages\django\core\handlers\base.py", line 197, in _get_response
    response = wrapped_callback(request, *callback_args, **callback_kwargs)
               ^^^^^^^^^^^^^^^^^^^^^^^^^^^^^^^^^^^^^^^^^^^^^^^^^^^^^^^^^^^^
  File "C:\Users\USER\OneDrive\video_editor\video_processing_app\video_processing\views.py", line 224, in video_status
    return JsonResponse({
                         ^
AttributeError: 'UploadedVideo' object has no attribute 'transcription'
ERROR 2025-01-11 16:56:40,399 basehttp "GET /api/videos/status/110/ HTTP/1.1" 500 69516
